2023-10-22 20:15:09,885 django.request ERROR    Internal Server Error: /api/books/
Traceback (most recent call last):
  File "/usr/local/lib/python3.10/site-packages/django/core/handlers/exception.py", line 55, in inner
    response = get_response(request)
  File "/usr/local/lib/python3.10/site-packages/django/core/handlers/base.py", line 197, in _get_response
    response = wrapped_callback(request, *callback_args, **callback_kwargs)
  File "/usr/local/lib/python3.10/site-packages/django/views/decorators/csrf.py", line 56, in wrapper_view
    return view_func(*args, **kwargs)
  File "/usr/local/lib/python3.10/site-packages/rest_framework/viewsets.py", line 125, in view
    return self.dispatch(request, *args, **kwargs)
  File "/usr/local/lib/python3.10/site-packages/rest_framework/views.py", line 509, in dispatch
    response = self.handle_exception(exc)
  File "/usr/local/lib/python3.10/site-packages/rest_framework/views.py", line 469, in handle_exception
    self.raise_uncaught_exception(exc)
  File "/usr/local/lib/python3.10/site-packages/rest_framework/views.py", line 480, in raise_uncaught_exception
    raise exc
  File "/usr/local/lib/python3.10/site-packages/rest_framework/views.py", line 506, in dispatch
    response = handler(request, *args, **kwargs)
  File "/usr/local/lib/python3.10/site-packages/rest_framework/mixins.py", line 18, in create
    serializer.is_valid(raise_exception=True)
  File "/usr/local/lib/python3.10/site-packages/rest_framework/serializers.py", line 227, in is_valid
    self._validated_data = self.run_validation(self.initial_data)
  File "/usr/local/lib/python3.10/site-packages/rest_framework/serializers.py", line 426, in run_validation
    value = self.to_internal_value(data)
  File "/usr/local/lib/python3.10/site-packages/rest_framework/serializers.py", line 483, in to_internal_value
    validated_value = field.run_validation(primitive_value)
  File "/usr/local/lib/python3.10/site-packages/rest_framework/fields.py", line 751, in run_validation
    return super().run_validation(data)
  File "/usr/local/lib/python3.10/site-packages/rest_framework/fields.py", line 548, in run_validation
    self.run_validators(value)
  File "/usr/local/lib/python3.10/site-packages/rest_framework/fields.py", line 560, in run_validators
    validator(value, self)
  File "/usr/local/lib/python3.10/site-packages/rest_framework/validators.py", line 73, in __call__
    if qs_exists(queryset):
  File "/usr/local/lib/python3.10/site-packages/rest_framework/validators.py", line 21, in qs_exists
    return queryset.exists()
  File "/usr/local/lib/python3.10/site-packages/django/db/models/query.py", line 1241, in exists
    return self.query.has_results(using=self.db)
  File "/usr/local/lib/python3.10/site-packages/django/db/models/sql/query.py", line 598, in has_results
    return compiler.has_results()
  File "/usr/local/lib/python3.10/site-packages/django/db/models/sql/compiler.py", line 1530, in has_results
    return bool(self.execute_sql(SINGLE))
  File "/usr/local/lib/python3.10/site-packages/django/db/models/sql/compiler.py", line 1560, in execute_sql
    cursor = self.connection.cursor()
  File "/usr/local/lib/python3.10/site-packages/django/utils/asyncio.py", line 26, in inner
    return func(*args, **kwargs)
  File "/usr/local/lib/python3.10/site-packages/django/db/backends/base/base.py", line 330, in cursor
    return self._cursor()
  File "/usr/local/lib/python3.10/site-packages/django/db/backends/base/base.py", line 306, in _cursor
    self.ensure_connection()
  File "/usr/local/lib/python3.10/site-packages/pytest_django/plugin.py", line 709, in _blocking_wrapper
    raise RuntimeError(
RuntimeError: Database access not allowed, use the "django_db" mark, or the "db" or "transactional_db" fixtures to enable it.
